Workbook
Name Expansion_Driver: ref!$D$3:$D$50
Name Expansion_Smart_IO: ref!$E$3:$E$34
Name Smart_IO: ref!$F$3:$F$10
Name 단독형_Smart_IO: ref!$F$3:$F$10
Name 증설_드라이브: ref!$D$3:$D$50
Name 증설형_Smart_IO: ref!$E$3:$E$34

Sheet XEL-BSSRx_Device mapping
U5: Offset = | V5: 0
B7: Slot | C7: Module Name | D7: Refresh Data [Byte] | F7: Total Refresh Data size [Byte] | H7: Byte Offset | M7: Aligning data on memory in side of LS PLC | Q7: Modbus Addr. Map (HEX) | U7: Modbus Addr. Map (Decimal) | Y7: Detailed Devices Info. | Z7: Input/Output | AA7: Flag | AB7: BIT/WORD | AC7: WORD(16BIT) Offset | AD7: Description
M8: Device type | N8: Start Addr. Read | O8: Device type | P8: Start Addr. Write | Q8: READING | R8: Counts | S8: WRITING | T8: Counts | U8: READING | V8: Counts | W8: WRITING | X8: Counts
D9: Input | E9: Output | F9: Input Refresh | G9: Output Refresh | H9: I | I9: Q | J9: U | K9: Input Refresh | L9: Output Refresh | M9: MW | N9: 0 | O9: MW | P9: 100 | R9: Word | T9: Word | V9: Word | X9: Word | Y9: Select slot
B10: Header | C10: Header | D10: 4 | E10: 0 | F10: =D10 -> 4 | G10: =E10 -> 0 | H10: - | I10: - | J10: - | K10: =IFERROR(F10-D10,0) -> 0 | L10: =IFERROR(G10-E10,"-") -> 0 | Q10: =IF(D10<>0,"H302"&TEXT(DEC2HEX(K10/2,2),"00"),0) -> H30200 | R10: =D10/2 -> 2 | S10: =IF(E10<>0,"H402"&TEXT(DEC2HEX(L10/2,2),"00"),0) -> 0 | T10: =E10/2 -> 0 | U10: =IF(D10<>0,"305"&TEXT(K10/2+12+$V$5,"00"),0) -> 30512 | V10: =D10/2 -> 2 | W10: =IF(E10<>0,"405"&TEXT(L10/2+12+$V$5,"00"),0) -> 0 | X10: =E10/2 -> 0 | Y10: 3 | Z10: =IFERROR(HLOOKUP(VLOOKUP((VLOOKUP($Y$10,$B$10:$C$22,2,FALSE)),'All data map'!$C$1:$J$3005,4,FALSE),IF($Y$14="XBE-DC08A",'All data map'!$F$1359:$J$1359, IF($Y$14="XBE-DC16A",'All data map'!$F$1360:$J$1360, IF($Y$14="XBE-DC16B",'All data map'!$F$1361:$J$1361, IF($Y$14="XBE-DC32A",'All data map'!$F$1362:$J$1362, IF($Y$14="XBE-AC08A",'All data map'!$F$1363:$J$1363, IF($Y$14="XBE-TN08A",'All data map'!$F$1364:$J$1364, IF($Y$14="XBE-TP08A",'All data map'!$F$1365:$J$1365, IF($Y$14="XBE-TN16A",'All data map'!$F$1366:$J$1366, IF($Y$14="XBE-TP16A",'All data map'!$F$1367:$J$1367, IF($Y$14="XBE-TN32A",'All data map'!$F$1368:$J$1368, IF($Y$14="XBE-TP32A",'All data map'!$F$1369:$J$1369, IF($Y$14="XBE-RY08A",'All data map'!$F$1370:$J$1370, IF($Y$14="XBE-RY08B",'All data map'!$F$1371:$J$1371, IF($Y$14="XBE-RY16A",'All data map'!$F$1372:$J$1372, IF($Y$14="XBE-DR16A",'All data map'!$F$1373:$J$1374, IF($Y$14="XBE-DN32A",'All data map'!$F$1375:$J$1376, IF($Y$14="XBF-AD04A",'All data map'!$F$1377:$J$1387, IF($Y$14="XBF-AD08A",'All data map'!$F$1388:$J$1422, IF($Y$14="XBF-AD04C",'All data map'!$F$1423:$J$1453, IF($Y$14="XBF-DV04A",'All data map'!$F$1454:$J$1470, IF($Y$14="XBF-DC04A",'All data map'!$F$1471:$J$1487, IF($Y$14="XBF-DC04B",'All data map'!$F$1488:$J$1504, IF($Y$14="XBF-DV04C",'All data map'!$F$1505:$J$1525, IF($Y$14="XBF-DC04C",'All data map'!$F$1526:$J$1550, IF($Y$14="XBF-AH04A",'All data map'!$F$1551:$J$1570, IF($Y$14="XBF-RD04A",'All data map'!$F$1571:$J$1590, IF($Y$14="XBF-RD01A",'All data map'!$F$1591:$J$1604, IF($Y$14="XBF-TC04B",'All data map'!$F$1605:$J$1650, IF($Y$14="XBF-TC04S",'All data map'!$F$1651:$J$1696, IF($Y$14="XBF-LD02S",'All data map'!$F$1697:$J$1805, IF($Y$14="XBF-HO02A",'All data map'!$F$1806:$J$1866, IF($Y$14="XBF-HD02A",'All data map'!$F$1867:$J$1927,IF($Y$14="Header",'All data map'!$F$2063:$J$2075,))))))))))))))))))))))))))))))))),BD10,FALSE),"-") -> Input | AA10: =IFERROR(HLOOKUP(VLOOKUP((VLOOKUP($Y$10,$B$10:$C$22,2,FALSE)),'All data map'!$C$1:$J$3005,5,FALSE),IF($Y$14="XBE-DC08A",'All data map'!$F$1359:$J$1359, IF($Y$14="XBE-DC16A",'All data map'!$F$1360:$J$1360, IF($Y$14="XBE-DC16B",'All data map'!$F$1361:$J$1361, IF($Y$14="XBE-DC32A",'All data map'!$F$1362:$J$1362, IF($Y$14="XBE-AC08A",'All data map'!$F$1363:$J$1363, IF($Y$14="XBE-TN08A",'All data map'!$F$1364:$J$1364, IF($Y$14="XBE-TP08A",'All data map'!$F$1365:$J$1365, IF($Y$14="XBE-TN16A",'All data map'!$F$1366:$J$1366, IF($Y$14="XBE-TP16A",'All data map'!$F$1367:$J$1367, IF($Y$14="XBE-TN32A",'All data map'!$F$1368:$J$1368, IF($Y$14="XBE-TP32A",'All data map'!$F$1369:$J$1369, IF($Y$14="XBE-RY08A",'All data map'!$F$1370:$J$1370, IF($Y$14="XBE-RY08B",'All data map'!$F$1371:$J$1371, IF($Y$14="XBE-RY16A",'All data map'!$F$1372:$J$1372, IF($Y$14="XBE-DR16A",'All data map'!$F$1373:$J$1374, IF($Y$14="XBE-DN32A",'All data map'!$F$1375:$J$1376, IF($Y$14="XBF-AD04A",'All data map'!$F$1377:$J$1387, IF($Y$14="XBF-AD08A",'All data map'!$F$1388:$J$1422, IF($Y$14="XBF-AD04C",'All data map'!$F$1423:$J$1453, IF($Y$14="XBF-DV04A",'All data map'!$F$1454:$J$1470, IF($Y$14="XBF-DC04A",'All data map'!$F$1471:$J$1487, IF($Y$14="XBF-DC04B",'All data map'!$F$1488:$J$1504, IF($Y$14="XBF-DV04C",'All data map'!$F$1505:$J$1525, IF($Y$14="XBF-DC04C",'All data map'!$F$1526:$J$1550, IF($Y$14="XBF-AH04A",'All data map'!$F$1551:$J$1570, IF($Y$14="XBF-RD04A",'All data map'!$F$1571:$J$1590, IF($Y$14="XBF-RD01A",'All data map'!$F$1591:$J$1604, IF($Y$14="XBF-TC04B",'All data map'!$F$1605:$J$1650, IF($Y$14="XBF-TC04S",'All data map'!$F$1651:$J$1696, IF($Y$14="XBF-LD02S",'All data map'!$F$1697:$J$1805, IF($Y$14="XBF-HO02A",'All data map'!$F$1806:$J$1866, IF($Y$14="XBF-HD02A",'All data map'!$F$1867:$J$1927,IF($Y$14="Header",'All data map'!$F$2063:$H$2075,0))))))))))))))))))))))))))))))))),BE10,FALSE),"-") -> XBF-TC04B_CH0_ADJERR | AB10: =IFERROR(HLOOKUP(VLOOKUP((VLOOKUP($Y$10,$B$10:$C$22,2,FALSE)),'All data map'!$C$1:$J$3005,6,FALSE),IF($Y$14="XBE-DC08A",'All data map'!$F$1359:$J$1359, IF($Y$14="XBE-DC16A",'All data map'!$F$1360:$J$1360, IF($Y$14="XBE-DC16B",'All data map'!$F$1361:$J$1361, IF($Y$14="XBE-DC32A",'All data map'!$F$1362:$J$1362, IF($Y$14="XBE-AC08A",'All data map'!$F$1363:$J$1363, IF($Y$14="XBE-TN08A",'All data map'!$F$1364:$J$1364, IF($Y$14="XBE-TP08A",'All data map'!$F$1365:$J$1365, IF($Y$14="XBE-TN16A",'All data map'!$F$1366:$J$1366, IF($Y$14="XBE-TP16A",'All data map'!$F$1367:$J$1367, IF($Y$14="XBE-TN32A",'All data map'!$F$1368:$J$1368, IF($Y$14="XBE-TP32A",'All data map'!$F$1369:$J$1369, IF($Y$14="XBE-RY08A",'All data map'!$F$1370:$J$1370, IF($Y$14="XBE-RY08B",'All data map'!$F$1371:$J$1371, IF($Y$14="XBE-RY16A",'All data map'!$F$1372:$J$1372, IF($Y$14="XBE-DR16A",'All data map'!$F$1373:$J$1374, IF($Y$14="XBE-DN32A",'All data map'!$F$1375:$J$1376, IF($Y$14="XBF-AD04A",'All data map'!$F$1377:$J$1387, IF($Y$14="XBF-AD08A",'All data map'!$F$1388:$J$1422, IF($Y$14="XBF-AD04C",'All data map'!$F$1423:$J$1453, IF($Y$14="XBF-DV04A",'All data map'!$F$1454:$J$1470, IF($Y$14="XBF-DC04A",'All data map'!$F$1471:$J$1487, IF($Y$14="XBF-DC04B",'All data map'!$F$1488:$J$1504, IF($Y$14="XBF-DV04C",'All data map'!$F$1505:$J$1525, IF($Y$14="XBF-DC04C",'All data map'!$F$1526:$J$1550, IF($Y$14="XBF-AH04A",'All data map'!$F$1551:$J$1570, IF($Y$14="XBF-RD04A",'All data map'!$F$1571:$J$1590, IF($Y$14="XBF-RD01A",'All data map'!$F$1591:$J$1604, IF($Y$14="XBF-TC04B",'All data map'!$F$1605:$J$1650, IF($Y$14="XBF-TC04S",'All data map'!$F$1651:$J$1696, IF($Y$14="XBF-LD02S",'All data map'!$F$1697:$J$1805, IF($Y$14="XBF-HO02A",'All data map'!$F$1806:$J$1866, IF($Y$14="XBF-HD02A",'All data map'!$F$1867:$J$1927,IF($Y$14="Header",'All data map'!$F$2063:$J$2075,))))))))))))))))))))))))))))))))),BF10,FALSE),"-") -> BIT | AC10: =IFERROR(HLOOKUP(VLOOKUP((VLOOKUP($Y$10,$B$10:$C$22,2,FALSE)),'All data map'!$C$1:$J$3005,7,FALSE),IF($Y$14="XBE-DC08A",'All data map'!$F$1359:$J$1359, IF($Y$14="XBE-DC16A",'All data map'!$F$1360:$J$1360, IF($Y$14="XBE-DC16B",'All data map'!$F$1361:$J$1361, IF($Y$14="XBE-DC32A",'All data map'!$F$1362:$J$1362, IF($Y$14="XBE-AC08A",'All data map'!$F$1363:$J$1363, IF($Y$14="XBE-TN08A",'All data map'!$F$1364:$J$1364, IF($Y$14="XBE-TP08A",'All data map'!$F$1365:$J$1365, IF($Y$14="XBE-TN16A",'All data map'!$F$1366:$J$1366, IF($Y$14="XBE-TP16A",'All data map'!$F$1367:$J$1367, IF($Y$14="XBE-TN32A",'All data map'!$F$1368:$J$1368, IF($Y$14="XBE-TP32A",'All data map'!$F$1369:$J$1369, IF($Y$14="XBE-RY08A",'All data map'!$F$1370:$J$1370, IF($Y$14="XBE-RY08B",'All data map'!$F$1371:$J$1371, IF($Y$14="XBE-RY16A",'All data map'!$F$1372:$J$1372, IF($Y$14="XBE-DR16A",'All data map'!$F$1373:$J$1374, IF($Y$14="XBE-DN32A",'All data map'!$F$1375:$J$1376, IF($Y$14="XBF-AD04A",'All data map'!$F$1377:$J$1387, IF($Y$14="XBF-AD08A",'All data map'!$F$1388:$J$1422, IF($Y$14="XBF-AD04C",'All data map'!$F$1423:$J$1453, IF($Y$14="XBF-DV04A",'All data map'!$F$1454:$J$1470, IF($Y$14="XBF-DC04A",'All data map'!$F$1471:$J$1487, IF($Y$14="XBF-DC04B",'All data map'!$F$1488:$J$1504, IF($Y$14="XBF-DV04C",'All data map'!$F$1505:$J$1525, IF($Y$14="XBF-DC04C",'All data map'!$F$1526:$J$1550, IF($Y$14="XBF-AH04A",'All data map'!$F$1551:$J$1570, IF($Y$14="XBF-RD04A",'All data map'!$F$1571:$J$1590, IF($Y$14="XBF-RD01A",'All data map'!$F$1591:$J$1604, IF($Y$14="XBF-TC04B",'All data map'!$F$1605:$J$1650, IF($Y$14="XBF-TC04S",'All data map'!$F$1651:$J$1696, IF($Y$14="XBF-LD02S",'All data map'!$F$1697:$J$1805, IF($Y$14="XBF-HO02A",'All data map'!$F$1806:$J$1866, IF($Y$14="XBF-HD02A",'All data map'!$F$1867:$J$1927,IF($Y$14="Header",'All data map'!$F$2063:$J$2075,))))))))))))))))))))))))))))))))),BG10,FALSE),"-") -> 0 | AD10: =IFERROR(HLOOKUP(VLOOKUP((VLOOKUP($Y$10,$B$10:$C$22,2,FALSE)),'All data map'!$C$1:$J$3005,8,FALSE),IF($Y$14="XBE-DC08A",'All data map'!$F$1359:$J$1359, IF($Y$14="XBE-DC16A",'All data map'!$F$1360:$J$1360, IF($Y$14="XBE-DC16B",'All data map'!$F$1361:$J$1361, IF($Y$14="XBE-DC32A",'All data map'!$F$1362:$J$1362, IF($Y$14="XBE-AC08A",'All data map'!$F$1363:$J$1363, IF($Y$14="XBE-TN08A",'All data map'!$F$1364:$J$1364, IF($Y$14="XBE-TP08A",'All data map'!$F$1365:$J$1365, IF($Y$14="XBE-TN16A",'All data map'!$F$1366:$J$1366, IF($Y$14="XBE-TP16A",'All data map'!$F$1367:$J$1367, IF($Y$14="XBE-TN32A",'All data map'!$F$1368:$J$1368, IF($Y$14="XBE-TP32A",'All data map'!$F$1369:$J$1369, IF($Y$14="XBE-RY08A",'All data map'!$F$1370:$J$1370, IF($Y$14="XBE-RY08B",'All data map'!$F$1371:$J$1371, IF($Y$14="XBE-RY16A",'All data map'!$F$1372:$J$1372, IF($Y$14="XBE-DR16A",'All data map'!$F$1373:$J$1374, IF($Y$14="XBE-DN32A",'All data map'!$F$1375:$J$1376, IF($Y$14="XBF-AD04A",'All data map'!$F$1377:$J$1387, IF($Y$14="XBF-AD08A",'All data map'!$F$1388:$J$1422, IF($Y$14="XBF-AD04C",'All data map'!$F$1423:$J$1453, IF($Y$14="XBF-DV04A",'All data map'!$F$1454:$J$1470, IF($Y$14="XBF-DC04A",'All data map'!$F$1471:$J$1487, IF($Y$14="XBF-DC04B",'All data map'!$F$1488:$J$1504, IF($Y$14="XBF-DV04C",'All data map'!$F$1505:$J$1525, IF($Y$14="XBF-DC04C",'All data map'!$F$1526:$J$1550, IF($Y$14="XBF-AH04A",'All data map'!$F$1551:$J$1570, IF($Y$14="XBF-RD04A",'All data map'!$F$1571:$J$1590, IF($Y$14="XBF-RD01A",'All data map'!$F$1591:$J$1604, IF($Y$14="XBF-TC04B",'All data map'!$F$1605:$J$1650, IF($Y$14="XBF-TC04S",'All data map'!$F$1651:$J$1696, IF($Y$14="XBF-LD02S",'All data map'!$F$1697:$J$1805, IF($Y$14="XBF-HO02A",'All data map'!$F$1806:$J$1866, IF($Y$14="XBF-HD02A",'All data map'!$F$1867:$J$1927,IF($Y$14="Header",'All data map'!$F$2063:$J$2075,))))))))))))))))))))))))))))))))),BH10,FALSE),"-") -> Temperature input module : Channel 0 offset/gain error flag | BB10: 1 | BC10: 1 | BD10: 1 | BE10: 1 | BF10: 1 | BG10: 1 | BH10: 1 | BI10: 1 | BJ10: 1 | BK10: 1 | BL10: 1 | BM10: 1 | BN10: 1 | BO10: 1 | BP10: 1 | BQ10: 1 | BR10: 1
B11: 0 | C11: XBE-DR16A | D11: =IFERROR(VLOOKUP(C11,'refresh size'!C:E,2,FALSE),0) -> 2 | E11: =IFERROR(VLOOKUP(C11,'refresh size'!C:E,3,FALSE),0) -> 2 | F11: =IF(LEN(C11)>0,IF(D11>0,MAX(F$10:F10)+D11,"-"),"-") -> 6 | G11: =IF(LEN(C11)>0,IF(E11>0,MAX(G$10:G10)+E11,0),0) -> 2 | H11: =B11*8 -> 0 | I11: =B11*8 -> 0 | J11: =B11*64 -> 0 | K11: =IFERROR(F11-D11,0) -> 4 | L11: =IFERROR(G11-E11,0) -> 0 | M11: =$M$9 -> MW | N11: =IF(D11,IF(D11,$N$9+(K11/2),0),"-") -> 2 | O11: =$M$9 -> MW | P11: =IF(E11,IF(E11,$P$9+(L11/2),0),"-") -> 100 | Q11: =IF(D11<>0,"H302"&TEXT(DEC2HEX(K11/2,2),"00"),0) -> H30202 | R11: =D11/2 -> 1 | S11: =IF(E11<>0,"H402"&TEXT(DEC2HEX(L11/2,2),"00"),0) -> H40200 | T11: =E11/2 -> 1 | U11: =IF(D11<>0,"305"&TEXT(K11/2+12+$V$5,"00"),0) -> 30514 | V11: =D11/2 -> 1 | W11: =IF(E11<>0,"405"&TEXT(L11/2+12+$V$5,"00"),0) -> 40512 | X11: =E11/2 -> 1 | Z11: =IFERROR(HLOOKUP(VLOOKUP((VLOOKUP($Y$10,$B$10:$C$22,2,FALSE)),'All data map'!$C$1:$J$3005,4,FALSE),IF($Y$14="XBE-DC08A",'All data map'!$F$1359:$J$1359, IF($Y$14="XBE-DC16A",'All data map'!$F$1360:$J$1360, IF($Y$14="XBE-DC16B",'All data map'!$F$1361:$J$1361, IF($Y$14="XBE-DC32A",'All data map'!$F$1362:$J$1362, IF($Y$14="XBE-AC08A",'All data map'!$F$1363:$J$1363, IF($Y$14="XBE-TN08A",'All data map'!$F$1364:$J$1364, IF($Y$14="XBE-TP08A",'All data map'!$F$1365:$J$1365, IF($Y$14="XBE-TN16A",'All data map'!$F$1366:$J$1366, IF($Y$14="XBE-TP16A",'All data map'!$F$1367:$J$1367, IF($Y$14="XBE-TN32A",'All data map'!$F$1368:$J$1368, IF($Y$14="XBE-TP32A",'All data map'!$F$1369:$J$1369, IF($Y$14="XBE-RY08A",'All data map'!$F$1370:$J$1370, IF($Y$14="XBE-RY08B",'All data map'!$F$1371:$J$1371, IF($Y$14="XBE-RY16A",'All data map'!$F$1372:$J$1372, IF($Y$14="XBE-DR16A",'All data map'!$F$1373:$J$1374, IF($Y$14="XBE-DN32A",'All data map'!$F$1375:$J$1376, IF($Y$14="XBF-AD04A",'All data map'!$F$1377:$J$1387, IF($Y$14="XBF-AD08A",'All data map'!$F$1388:$J$1422, IF($Y$14="XBF-AD04C",'All data map'!$F$1423:$J$1453, IF($Y$14="XBF-DV04A",'All data map'!$F$1454:$J$1470, IF($Y$14="XBF-DC04A",'All data map'!$F$1471:$J$1487, IF($Y$14="XBF-DC04B",'All data map'!$F$1488:$J$1504, IF($Y$14="XBF-DV04C",'All data map'!$F$1505:$J$1525, IF($Y$14="XBF-DC04C",'All data map'!$F$1526:$J$1550, IF($Y$14="XBF-AH04A",'All data map'!$F$1551:$J$1570, IF($Y$14="XBF-RD04A",'All data map'!$F$1571:$J$1590, IF($Y$14="XBF-RD01A",'All data map'!$F$1591:$J$1604, IF($Y$14="XBF-TC04B",'All data map'!$F$1605:$J$1650, IF($Y$14="XBF-TC04S",'All data map'!$F$1651:$J$1696, IF($Y$14="XBF-LD02S",'All data map'!$F$1697:$J$1805, IF($Y$14="XBF-HO02A",'All data map'!$F$1806:$J$1866, IF($Y$14="XBF-HD02A",'All data map'!$F$1867:$J$1927,IF($Y$14="Header",'All data map'!$F$2063:$J$2075,))))))))))))))))))))))))))))))))),BD11,FALSE),"-") -> Input | AA11: =IFERROR(HLOOKUP(VLOOKUP((VLOOKUP($Y$10,$B$10:$C$22,2,FALSE)),'All data map'!$C$1:$J$3005,5,FALSE),IF($Y$14="XBE-DC08A",'All data map'!$F$1359:$J$1359, IF($Y$14="XBE-DC16A",'All data map'!$F$1360:$J$1360, IF($Y$14="XBE-DC16B",'All data map'!$F$1361:$J$1361, IF($Y$14="XBE-DC32A",'All data map'!$F$1362:$J$1362, IF($Y$14="XBE-AC08A",'All data map'!$F$1363:$J$1363, IF($Y$14="XBE-TN08A",'All data map'!$F$1364:$J$1364, IF($Y$14="XBE-TP08A",'All data map'!$F$1365:$J$1365, IF($Y$14="XBE-TN16A",'All data map'!$F$1366:$J$1366, IF($Y$14="XBE-TP16A",'All data map'!$F$1367:$J$1367, IF($Y$14="XBE-TN32A",'All data map'!$F$1368:$J$1368, IF($Y$14="XBE-TP32A",'All data map'!$F$1369:$J$1369, IF($Y$14="XBE-RY08A",'All data map'!$F$1370:$J$1370, IF($Y$14="XBE-RY08B",'All data map'!$F$1371:$J$1371, IF($Y$14="XBE-RY16A",'All data map'!$F$1372:$J$1372, IF($Y$14="XBE-DR16A",'All data map'!$F$1373:$J$1374, IF($Y$14="XBE-DN32A",'All data map'!$F$1375:$J$1376, IF($Y$14="XBF-AD04A",'All data map'!$F$1377:$J$1387, IF($Y$14="XBF-AD08A",'All data map'!$F$1388:$J$1422, IF($Y$14="XBF-AD04C",'All data map'!$F$1423:$J$1453, IF($Y$14="XBF-DV04A",'All data map'!$F$1454:$J$1470, IF($Y$14="XBF-DC04A",'All data map'!$F$1471:$J$1487, IF($Y$14="XBF-DC04B",'All data map'!$F$1488:$J$1504, IF($Y$14="XBF-DV04C",'All data map'!$F$1505:$J$1525, IF($Y$14="XBF-DC04C",'All data map'!$F$1526:$J$1550, IF($Y$14="XBF-AH04A",'All data map'!$F$1551:$J$1570, IF($Y$14="XBF-RD04A",'All data map'!$F$1571:$J$1590, IF($Y$14="XBF-RD01A",'All data map'!$F$1591:$J$1604, IF($Y$14="XBF-TC04B",'All data map'!$F$1605:$J$1650, IF($Y$14="XBF-TC04S",'All data map'!$F$1651:$J$1696, IF($Y$14="XBF-LD02S",'All data map'!$F$1697:$J$1805, IF($Y$14="XBF-HO02A",'All data map'!$F$1806:$J$1866, IF($Y$14="XBF-HD02A",'All data map'!$F$1867:$J$1927,IF($Y$14="Header",'All data map'!$F$2063:$H$2075,0))))))))))))))))))))))))))))))))),BE11,FALSE),"-") -> XBF-TC04B_CH1_ADJERR | AB11: =IFERROR(HLOOKUP(VLOOKUP((VLOOKUP($Y$10,$B$10:$C$22,2,FALSE)),'All data map'!$C$1:$J$3005,6,FALSE),IF($Y$14="XBE-DC08A",'All data map'!$F$1359:$J$1359, IF($Y$14="XBE-DC16A",'All data map'!$F$1360:$J$1360, IF($Y$14="XBE-DC16B",'All data map'!$F$1361:$J$1361, IF($Y$14="XBE-DC32A",'All data map'!$F$1362:$J$1362, IF($Y$14="XBE-AC08A",'All data map'!$F$1363:$J$1363, IF($Y$14="XBE-TN08A",'All data map'!$F$1364:$J$1364, IF($Y$14="XBE-TP08A",'All data map'!$F$1365:$J$1365, IF($Y$14="XBE-TN16A",'All data map'!$F$1366:$J$1366, IF($Y$14="XBE-TP16A",'All data map'!$F$1367:$J$1367, IF($Y$14="XBE-TN32A",'All data map'!$F$1368:$J$1368, IF($Y$14="XBE-TP32A",'All data map'!$F$1369:$J$1369, IF($Y$14="XBE-RY08A",'All data map'!$F$1370:$J$1370, IF($Y$14="XBE-RY08B",'All data map'!$F$1371:$J$1371, IF($Y$14="XBE-RY16A",'All data map'!$F$1372:$J$1372, IF($Y$14="XBE-DR16A",'All data map'!$F$1373:$J$1374, IF($Y$14="XBE-DN32A",'All data map'!$F$1375:$J$1376, IF($Y$14="XBF-AD04A",'All data map'!$F$1377:$J$1387, IF($Y$14="XBF-AD08A",'All data map'!$F$1388:$J$1422, IF($Y$14="XBF-AD04C",'All data map'!$F$1423:$J$1453, IF($Y$14="XBF-DV04A",'All data map'!$F$1454:$J$1470, IF($Y$14="XBF-DC04A",'All data map'!$F$1471:$J$1487, IF($Y$14="XBF-DC04B",'All data map'!$F$1488:$J$1504, IF($Y$14="XBF-DV04C",'All data map'!$F$1505:$J$1525, IF($Y$14="XBF-DC04C",'All data map'!$F$1526:$J$1550, IF($Y$14="XBF-AH04A",'All data map'!$F$1551:$J$1570, IF($Y$14="XBF-RD04A",'All data map'!$F$1571:$J$1590, IF($Y$14="XBF-RD01A",'All data map'!$F$1591:$J$1604, IF($Y$14="XBF-TC04B",'All data map'!$F$1605:$J$1650, IF($Y$14="XBF-TC04S",'All data map'!$F$1651:$J$1696, IF($Y$14="XBF-LD02S",'All data map'!$F$1697:$J$1805, IF($Y$14="XBF-HO02A",'All data map'!$F$1806:$J$1866, IF($Y$14="XBF-HD02A",'All data map'!$F$1867:$J$1927,IF($Y$14="Header",'All data map'!$F$2063:$J$2075,))))))))))))))))))))))))))))))))),BF11,FALSE),"-") -> BIT | AC11: =IFERROR(HLOOKUP(VLOOKUP((VLOOKUP($Y$10,$B$10:$C$22,2,FALSE)),'All data map'!$C$1:$J$3005,7,FALSE),IF($Y$14="XBE-DC08A",'All data map'!$F$1359:$J$1359, IF($Y$14="XBE-DC16A",'All data map'!$F$1360:$J$1360, IF($Y$14="XBE-DC16B",'All data map'!$F$1361:$J$1361, IF($Y$14="XBE-DC32A",'All data map'!$F$1362:$J$1362, IF($Y$14="XBE-AC08A",'All data map'!$F$1363:$J$1363, IF($Y$14="XBE-TN08A",'All data map'!$F$1364:$J$1364, IF($Y$14="XBE-TP08A",'All data map'!$F$1365:$J$1365, IF($Y$14="XBE-TN16A",'All data map'!$F$1366:$J$1366, IF($Y$14="XBE-TP16A",'All data map'!$F$1367:$J$1367, IF($Y$14="XBE-TN32A",'All data map'!$F$1368:$J$1368, IF($Y$14="XBE-TP32A",'All data map'!$F$1369:$J$1369, IF($Y$14="XBE-RY08A",'All data map'!$F$1370:$J$1370, IF($Y$14="XBE-RY08B",'All data map'!$F$1371:$J$1371, IF($Y$14="XBE-RY16A",'All data map'!$F$1372:$J$1372, IF($Y$14="XBE-DR16A",'All data map'!$F$1373:$J$1374, IF($Y$14="XBE-DN32A",'All data map'!$F$1375:$J$1376, IF($Y$14="XBF-AD04A",'All data map'!$F$1377:$J$1387, IF($Y$14="XBF-AD08A",'All data map'!$F$1388:$J$1422, IF($Y$14="XBF-AD04C",'All data map'!$F$1423:$J$1453, IF($Y$14="XBF-DV04A",'All data map'!$F$1454:$J$1470, IF($Y$14="XBF-DC04A",'All data map'!$F$1471:$J$1487, IF($Y$14="XBF-DC04B",'All data map'!$F$1488:$J$1504, IF($Y$14="XBF-DV04C",'All data map'!$F$1505:$J$1525, IF($Y$14="XBF-DC04C",'All data map'!$F$1526:$J$1550, IF($Y$14="XBF-AH04A",'All data map'!$F$1551:$J$1570, IF($Y$14="XBF-RD04A",'All data map'!$F$1571:$J$1590, IF($Y$14="XBF-RD01A",'All data map'!$F$1591:$J$1604, IF($Y$14="XBF-TC04B",'All data map'!$F$1605:$J$1650, IF($Y$14="XBF-TC04S",'All data map'!$F$1651:$J$1696, IF($Y$14="XBF-LD02S",'All data map'!$F$1697:$J$1805, IF($Y$14="XBF-HO02A",'All data map'!$F$1806:$J$1866, IF($Y$14="XBF-HD02A",'All data map'!$F$1867:$J$1927,IF($Y$14="Header",'All data map'!$F$2063:$J$2075,))))))))))))))))))))))))))))))))),BG11,FALSE),"-") -> 0.1 | AD11: =IFERROR(HLOOKUP(VLOOKUP((VLOOKUP($Y$10,$B$10:$C$22,2,FALSE)),'All data map'!$C$1:$J$3005,8,FALSE),IF($Y$14="XBE-DC08A",'All data map'!$F$1359:$J$1359, IF($Y$14="XBE-DC16A",'All data map'!$F$1360:$J$1360, IF($Y$14="XBE-DC16B",'All data map'!$F$1361:$J$1361, IF($Y$14="XBE-DC32A",'All data map'!$F$1362:$J$1362, IF($Y$14="XBE-AC08A",'All data map'!$F$1363:$J$1363, IF($Y$14="XBE-TN08A",'All data map'!$F$1364:$J$1364, IF($Y$14="XBE-TP08A",'All data map'!$F$1365:$J$1365, IF($Y$14="XBE-TN16A",'All data map'!$F$1366:$J$1366, IF($Y$14="XBE-TP16A",'All data map'!$F$1367:$J$1367, IF($Y$14="XBE-TN32A",'All data map'!$F$1368:$J$1368, IF($Y$14="XBE-TP32A",'All data map'!$F$1369:$J$1369, IF($Y$14="XBE-RY08A",'All data map'!$F$1370:$J$1370, IF($Y$14="XBE-RY08B",'All data map'!$F$1371:$J$1371, IF($Y$14="XBE-RY16A",'All data map'!$F$1372:$J$1372, IF($Y$14="XBE-DR16A",'All data map'!$F$1373:$J$1374, IF($Y$14="XBE-DN32A",'All data map'!$F$1375:$J$1376, IF($Y$14="XBF-AD04A",'All data map'!$F$1377:$J$1387, IF($Y$14="XBF-AD08A",'All data map'!$F$1388:$J$1422, IF($Y$14="XBF-AD04C",'All data map'!$F$1423:$J$1453, IF($Y$14="XBF-DV04A",'All data map'!$F$1454:$J$1470, IF($Y$14="XBF-DC04A",'All data map'!$F$1471:$J$1487, IF($Y$14="XBF-DC04B",'All data map'!$F$1488:$J$1504, IF($Y$14="XBF-DV04C",'All data map'!$F$1505:$J$1525, IF($Y$14="XBF-DC04C",'All data map'!$F$1526:$J$1550, IF($Y$14="XBF-AH04A",'All data map'!$F$1551:$J$1570, IF($Y$14="XBF-RD04A",'All data map'!$F$1571:$J$1590, IF($Y$14="XBF-RD01A",'All data map'!$F$1591:$J$1604, IF($Y$14="XBF-TC04B",'All data map'!$F$1605:$J$1650, IF($Y$14="XBF-TC04S",'All data map'!$F$1651:$J$1696, IF($Y$14="XBF-LD02S",'All data map'!$F$1697:$J$1805, IF($Y$14="XBF-HO02A",'All data map'!$F$1806:$J$1866, IF($Y$14="XBF-HD02A",'All data map'!$F$1867:$J$1927,IF($Y$14="Header",'All data map'!$F$2063:$J$2075,))))))))))))))))))))))))))))))))),BH11,FALSE),"-") -> Temperature input module : Channel 1 offset/gain error flag | BB11: 2 | BC11: 2 | BD11: 2 | BE11: 2 | BF11: 2 | BG11: 2 | BH11: 2 | BI11: 2 | BJ11: 2 | BK11: 2 | BL11: 2 | BM11: 2 | BN11: 2 | BO11: 2 | BP11: 2 | BQ11: 2 | BR11: 2
B12: 1 | C12: XBF-DV04A | D12: =IFERROR(VLOOKUP(C12,'refresh size'!C:E,2,FALSE),0) -> 4 | E12: =IFERROR(VLOOKUP(C12,'refresh size'!C:E,3,FALSE),0) -> 10 | F12: =IF(LEN(C12)>0,IF(D12>0,MAX(F$10:F11)+D12,"-"),"-") -> 10 | G12: =IF(LEN(C12)>0,IF(E12>0,MAX(G$10:G11)+E12,0),0) -> 12 | H12: =B12*8 -> 8 | I12: =B12*8 -> 8 | J12: =B12*64 -> 64 | K12: =IFERROR(F12-D12,0) -> 6 | L12: =IFERROR(G12-E12,0) -> 2 | M12: =$M$9 -> MW | N12: =IF(D12,IF(D12,$N$9+(K12/2),0),"-") -> 3 | O12: =$M$9 -> MW | P12: =IF(E12,IF(E12,$P$9+(L12/2),0),"-") -> 101 | Q12: =IF(D12<>0,"H302"&TEXT(DEC2HEX(K12/2,2),"00"),0) -> H30203 | R12: =D12/2 -> 2 | S12: =IF(E12<>0,"H402"&TEXT(DEC2HEX(L12/2,2),"00"),0) -> H40201 | T12: =E12/2 -> 5 | U12: =IF(D12<>0,"305"&TEXT(K12/2+12+$V$5,"00"),0) -> 30515 | V12: =D12/2 -> 2 | W12: =IF(E12<>0,"405"&TEXT(L12/2+12+$V$5,"00"),0) -> 40513 | X12: =E12/2 -> 5 | Z12: =IFERROR(HLOOKUP(VLOOKUP((VLOOKUP($Y$10,$B$10:$C$22,2,FALSE)),'All data map'!$C$1:$J$3005,4,FALSE),IF($Y$14="XBE-DC08A",'All data map'!$F$1359:$J$1359, IF($Y$14="XBE-DC16A",'All data map'!$F$1360:$J$1360, IF($Y$14="XBE-DC16B",'All data map'!$F$1361:$J$1361, IF($Y$14="XBE-DC32A",'All data map'!$F$1362:$J$1362, IF($Y$14="XBE-AC08A",'All data map'!$F$1363:$J$1363, IF($Y$14="XBE-TN08A",'All data map'!$F$1364:$J$1364, IF($Y$14="XBE-TP08A",'All data map'!$F$1365:$J$1365, IF($Y$14="XBE-TN16A",'All data map'!$F$1366:$J$1366, IF($Y$14="XBE-TP16A",'All data map'!$F$1367:$J$1367, IF($Y$14="XBE-TN32A",'All data map'!$F$1368:$J$1368, IF($Y$14="XBE-TP32A",'All data map'!$F$1369:$J$1369, IF($Y$14="XBE-RY08A",'All data map'!$F$1370:$J$1370, IF($Y$14="XBE-RY08B",'All data map'!$F$1371:$J$1371, IF($Y$14="XBE-RY16A",'All data map'!$F$1372:$J$1372, IF($Y$14="XBE-DR16A",'All data map'!$F$1373:$J$1374, IF($Y$14="XBE-DN32A",'All data map'!$F$1375:$J$1376, IF($Y$14="XBF-AD04A",'All data map'!$F$1377:$J$1387, IF($Y$14="XBF-AD08A",'All data map'!$F$1388:$J$1422, IF($Y$14="XBF-AD04C",'All data map'!$F$1423:$J$1453, IF($Y$14="XBF-DV04A",'All data map'!$F$1454:$J$1470, IF($Y$14="XBF-DC04A",'All data map'!$F$1471:$J$1487, IF($Y$14="XBF-DC04B",'All data map'!$F$1488:$J$1504, IF($Y$14="XBF-DV04C",'All data map'!$F$1505:$J$1525, IF($Y$14="XBF-DC04C",'All data map'!$F$1526:$J$1550, IF($Y$14="XBF-AH04A",'All data map'!$F$1551:$J$1570, IF($Y$14="XBF-RD04A",'All data map'!$F$1571:$J$1590, IF($Y$14="XBF-RD01A",'All data map'!$F$1591:$J$1604, IF($Y$14="XBF-TC04B",'All data map'!$F$1605:$J$1650, IF($Y$14="XBF-TC04S",'All data map'!$F$1651:$J$1696, IF($Y$14="XBF-LD02S",'All data map'!$F$1697:$J$1805, IF($Y$14="XBF-HO02A",'All data map'!$F$1806:$J$1866, IF($Y$14="XBF-HD02A",'All data map'!$F$1867:$J$1927,IF($Y$14="Header",'All data map'!$F$2063:$J$2075,))))))))))))))))))))))))))))))))),BD12,FALSE),"-") -> Input | AA12: =IFERROR(HLOOKUP(VLOOKUP((VLOOKUP($Y$10,$B$10:$C$22,2,FALSE)),'All data map'!$C$1:$J$3005,5,FALSE),IF($Y$14="XBE-DC08A",'All data map'!$F$1359:$J$1359, IF($Y$14="XBE-DC16A",'All data map'!$F$1360:$J$1360, IF($Y$14="XBE-DC16B",'All data map'!$F$1361:$J$1361, IF($Y$14="XBE-DC32A",'All data map'!$F$1362:$J$1362, IF($Y$14="XBE-AC08A",'All data map'!$F$1363:$J$1363, IF($Y$14="XBE-TN08A",'All data map'!$F$1364:$J$1364, IF($Y$14="XBE-TP08A",'All data map'!$F$1365:$J$1365, IF($Y$14="XBE-TN16A",'All data map'!$F$1366:$J$1366, IF($Y$14="XBE-TP16A",'All data map'!$F$1367:$J$1367, IF($Y$14="XBE-TN32A",'All data map'!$F$1368:$J$1368, IF($Y$14="XBE-TP32A",'All data map'!$F$1369:$J$1369, IF($Y$14="XBE-RY08A",'All data map'!$F$1370:$J$1370, IF($Y$14="XBE-RY08B",'All data map'!$F$1371:$J$1371, IF($Y$14="XBE-RY16A",'All data map'!$F$1372:$J$1372, IF($Y$14="XBE-DR16A",'All data map'!$F$1373:$J$1374, IF($Y$14="XBE-DN32A",'All data map'!$F$1375:$J$1376, IF($Y$14="XBF-AD04A",'All data map'!$F$1377:$J$1387, IF($Y$14="XBF-AD08A",'All data map'!$F$1388:$J$1422, IF($Y$14="XBF-AD04C",'All data map'!$F$1423:$J$1453, IF($Y$14="XBF-DV04A",'All data map'!$F$1454:$J$1470, IF($Y$14="XBF-DC04A",'All data map'!$F$1471:$J$1487, IF($Y$14="XBF-DC04B",'All data map'!$F$1488:$J$1504, IF($Y$14="XBF-DV04C",'All data map'!$F$1505:$J$1525, IF($Y$14="XBF-DC04C",'All data map'!$F$1526:$J$1550, IF($Y$14="XBF-AH04A",'All data map'!$F$1551:$J$1570, IF($Y$14="XBF-RD04A",'All data map'!$F$1571:$J$1590, IF($Y$14="XBF-RD01A",'All data map'!$F$1591:$J$1604, IF($Y$14="XBF-TC04B",'All data map'!$F$1605:$J$1650, IF($Y$14="XBF-TC04S",'All data map'!$F$1651:$J$1696, IF($Y$14="XBF-LD02S",'All data map'!$F$1697:$J$1805, IF($Y$14="XBF-HO02A",'All data map'!$F$1806:$J$1866, IF($Y$14="XBF-HD02A",'All data map'!$F$1867:$J$1927,IF($Y$14="Header",'All data map'!$F$2063:$H$2075,0))))))))))))))))))))))))))))))))),BE12,FALSE),"-") -> XBF-TC04B_CH2_ADJERR | AB12: =IFERROR(HLOOKUP(VLOOKUP((VLOOKUP($Y$10,$B$10:$C$22,2,FALSE)),'All data map'!$C$1:$J$3005,6,FALSE),IF($Y$14="XBE-DC08A",'All data map'!$F$1359:$J$1359, IF($Y$14="XBE-DC16A",'All data map'!$F$1360:$J$1360, IF($Y$14="XBE-DC16B",'All data map'!$F$1361:$J$1361, IF($Y$14="XBE-DC32A",'All data map'!$F$1362:$J$1362, IF($Y$14="XBE-AC08A",'All data map'!$F$1363:$J$1363, IF($Y$14="XBE-TN08A",'All data map'!$F$1364:$J$1364, IF($Y$14="XBE-TP08A",'All data map'!$F$1365:$J$1365, IF($Y$14="XBE-TN16A",'All data map'!$F$1366:$J$1366, IF($Y$14="XBE-TP16A",'All data map'!$F$1367:$J$1367, IF($Y$14="XBE-TN32A",'All data map'!$F$1368:$J$1368, IF($Y$14="XBE-TP32A",'All data map'!$F$1369:$J$1369, IF($Y$14="XBE-RY08A",'All data map'!$F$1370:$J$1370, IF($Y$14="XBE-RY08B",'All data map'!$F$1371:$J$1371, IF($Y$14="XBE-RY16A",'All data map'!$F$1372:$J$1372, IF($Y$14="XBE-DR16A",'All data map'!$F$1373:$J$1374, IF($Y$14="XBE-DN32A",'All data map'!$F$1375:$J$1376, IF($Y$14="XBF-AD04A",'All data map'!$F$1377:$J$1387, IF($Y$14="XBF-AD08A",'All data map'!$F$1388:$J$1422, IF($Y$14="XBF-AD04C",'All data map'!$F$1423:$J$1453, IF($Y$14="XBF-DV04A",'All data map'!$F$1454:$J$1470, IF($Y$14="XBF-DC04A",'All data map'!$F$1471:$J$1487, IF($Y$14="XBF-DC04B",'All data map'!$F$1488:$J$1504, IF($Y$14="XBF-DV04C",'All data map'!$F$1505:$J$1525, IF($Y$14="XBF-DC04C",'All data map'!$F$1526:$J$1550, IF($Y$14="XBF-AH04A",'All data map'!$F$1551:$J$1570, IF($Y$14="XBF-RD04A",'All data map'!$F$1571:$J$1590, IF($Y$14="XBF-RD01A",'All data map'!$F$1591:$J$1604, IF($Y$14="XBF-TC04B",'All data map'!$F$1605:$J$1650, IF($Y$14="XBF-TC04S",'All data map'!$F$1651:$J$1696, IF($Y$14="XBF-LD02S",'All data map'!$F$1697:$J$1805, IF($Y$14="XBF-HO02A",'All data map'!$F$1806:$J$1866, IF($Y$14="XBF-HD02A",'All data map'!$F$1867:$J$1927,IF($Y$14="Header",'All data map'!$F$2063:$J$2075,))))))))))))))))))))))))))))))))),BF12,FALSE),"-") -> BIT | AC12: =IFERROR(HLOOKUP(VLOOKUP((VLOOKUP($Y$10,$B$10:$C$22,2,FALSE)),'All data map'!$C$1:$J$3005,7,FALSE),IF($Y$14="XBE-DC08A",'All data map'!$F$1359:$J$1359, IF($Y$14="XBE-DC16A",'All data map'!$F$1360:$J$1360, IF($Y$14="XBE-DC16B",'All data map'!$F$1361:$J$1361, IF($Y$14="XBE-DC32A",'All data map'!$F$1362:$J$1362, IF($Y$14="XBE-AC08A",'All data map'!$F$1363:$J$1363, IF($Y$14="XBE-TN08A",'All data map'!$F$1364:$J$1364, IF($Y$14="XBE-TP08A",'All data map'!$F$1365:$J$1365, IF($Y$14="XBE-TN16A",'All data map'!$F$1366:$J$1366, IF($Y$14="XBE-TP16A",'All data map'!$F$1367:$J$1367, IF($Y$14="XBE-TN32A",'All data map'!$F$1368:$J$1368, IF($Y$14="XBE-TP32A",'All data map'!$F$1369:$J$1369, IF($Y$14="XBE-RY08A",'All data map'!$F$1370:$J$1370, IF($Y$14="XBE-RY08B",'All data map'!$F$1371:$J$1371, IF($Y$14="XBE-RY16A",'All data map'!$F$1372:$J$1372, IF($Y$14="XBE-DR16A",'All data map'!$F$1373:$J$1374, IF($Y$14="XBE-DN32A",'All data map'!$F$1375:$J$1376, IF($Y$14="XBF-AD04A",'All data map'!$F$1377:$J$1387, IF($Y$14="XBF-AD08A",'All data map'!$F$1388:$J$1422, IF($Y$14="XBF-AD04C",'All data map'!$F$1423:$J$1453, IF($Y$14="XBF-DV04A",'All data map'!$F$1454:$J$1470, IF($Y$14="XBF-DC04A",'All data map'!$F$1471:$J$1487, IF($Y$14="XBF-DC04B",'All data map'!$F$1488:$J$1504, IF($Y$14="XBF-DV04C",'All data map'!$F$1505:$J$1525, IF($Y$14="XBF-DC04C",'All data map'!$F$1526:$J$1550, IF($Y$14="XBF-AH04A",'All data map'!$F$1551:$J$1570, IF($Y$14="XBF-RD04A",'All data map'!$F$1571:$J$1590, IF($Y$14="XBF-RD01A",'All data map'!$F$1591:$J$1604, IF($Y$14="XBF-TC04B",'All data map'!$F$1605:$J$1650, IF($Y$14="XBF-TC04S",'All data map'!$F$1651:$J$1696, IF($Y$14="XBF-LD02S",'All data map'!$F$1697:$J$1805, IF($Y$14="XBF-HO02A",'All data map'!$F$1806:$J$1866, IF($Y$14="XBF-HD02A",'All data map'!$F$1867:$J$1927,IF($Y$14="Header",'All data map'!$F$2063:$J$2075,))))))))))))))))))))))))))))))))),BG12,FALSE),"-") -> 0.2 | AD12: =IFERROR(HLOOKUP(VLOOKUP((VLOOKUP($Y$10,$B$10:$C$22,2,FALSE)),'All data map'!$C$1:$J$3005,8,FALSE),IF($Y$14="XBE-DC08A",'All data map'!$F$1359:$J$1359, IF($Y$14="XBE-DC16A",'All data map'!$F$1360:$J$1360, IF($Y$14="XBE-DC16B",'All data map'!$F$1361:$J$1361, IF($Y$14="XBE-DC32A",'All data map'!$F$1362:$J$1362, IF($Y$14="XBE-AC08A",'All data map'!$F$1363:$J$1363, IF($Y$14="XBE-TN08A",'All data map'!$F$1364:$J$1364, IF($Y$14="XBE-TP08A",'All data map'!$F$1365:$J$1365, IF($Y$14="XBE-TN16A",'All data map'!$F$1366:$J$1366, IF($Y$14="XBE-TP16A",'All data map'!$F$1367:$J$1367, IF($Y$14="XBE-TN32A",'All data map'!$F$1368:$J$1368, IF($Y$14="XBE-TP32A",'All data map'!$F$1369:$J$1369, IF($Y$14="XBE-RY08A",'All data map'!$F$1370:$J$1370, IF($Y$14="XBE-RY08B",'All data map'!$F$1371:$J$1371, IF($Y$14="XBE-RY16A",'All data map'!$F$1372:$J$1372, IF($Y$14="XBE-DR16A",'All data map'!$F$1373:$J$1374, IF($Y$14="XBE-DN32A",'All data map'!$F$1375:$J$1376, IF($Y$14="XBF-AD04A",'All data map'!$F$1377:$J$1387, IF($Y$14="XBF-AD08A",'All data map'!$F$1388:$J$1422, IF($Y$14="XBF-AD04C",'All data map'!$F$1423:$J$1453, IF($Y$14="XBF-DV04A",'All data map'!$F$1454:$J$1470, IF($Y$14="XBF-DC04A",'All data map'!$F$1471:$J$1487, IF($Y$14="XBF-DC04B",'All data map'!$F$1488:$J$1504, IF($Y$14="XBF-DV04C",'All data map'!$F$1505:$J$1525, IF($Y$14="XBF-DC04C",'All data map'!$F$1526:$J$1550, IF($Y$14="XBF-AH04A",'All data map'!$F$1551:$J$1570, IF($Y$14="XBF-RD04A",'All data map'!$F$1571:$J$1590, IF($Y$14="XBF-RD01A",'All data map'!$F$1591:$J$1604, IF($Y$14="XBF-TC04B",'All data map'!$F$1605:$J$1650, IF($Y$14="XBF-TC04S",'All data map'!$F$1651:$J$1696, IF($Y$14="XBF-LD02S",'All data map'!$F$1697:$J$1805, IF($Y$14="XBF-HO02A",'All data map'!$F$1806:$J$1866, IF($Y$14="XBF-HD02A",'All data map'!$F$1867:$J$1927,IF($Y$14="Header",'All data map'!$F$2063:$J$2075,))))))))))))))))))))))))))))))))),BH12,FALSE),"-") -> Temperature input module : Channel 2 offset/gain error flag | BB12: 3 | BC12: 3 | BD12: 3 | BE12: 3 | BF12: 3 | BG12: 3 | BH12: 3 | BI12: 3 | BJ12: 3 | BK12: 3 | BL12: 3 | BM12: 3 | BN12: 3 | BO12: 3 | BP12: 3 | BQ12: 3 | BR12: 3
B13: 2 | C13: XBF-AH04A | D13: =IFERROR(VLOOKUP(C13,'refresh size'!C:E,2,FALSE),0) -> 12 | E13: =IFERROR(VLOOKUP(C13,'refresh size'!C:E,3,FALSE),0) -> 6 | F13: =IF(LEN(C13)>0,IF(D13>0,MAX(F$10:F12)+D13,"-"),"-") -> 22 | G13: =IF(LEN(C13)>0,IF(E13>0,MAX(G$10:G12)+E13,0),0) -> 18 | H13: =B13*8 -> 16 | I13: =B13*8 -> 16 | J13: =B13*64 -> 128 | K13: =IFERROR(F13-D13,0) -> 10 | L13: =IFERROR(G13-E13,0) -> 12 | M13: =$M$9 -> MW | N13: =IF(D13,IF(D13,$N$9+(K13/2),0),"-") -> 5 | O13: =$M$9 -> MW | P13: =IF(E13,IF(E13,$P$9+(L13/2),0),"-") -> 106 | Q13: =IF(D13<>0,"H302"&TEXT(DEC2HEX(K13/2,2),"00"),0) -> H30205 | R13: =D13/2 -> 6 | S13: =IF(E13<>0,"H402"&TEXT(DEC2HEX(L13/2,2),"00"),0) -> H40206 | T13: =E13/2 -> 3 | U13: =IF(D13<>0,"305"&TEXT(K13/2+12+$V$5,"00"),0) -> 30517 | V13: =D13/2 -> 6 | W13: =IF(E13<>0,"405"&TEXT(L13/2+12+$V$5,"00"),0) -> 40518 | X13: =E13/2 -> 3 | Y13: Product Name | Z13: =IFERROR(HLOOKUP(VLOOKUP((VLOOKUP($Y$10,$B$10:$C$22,2,FALSE)),'All data map'!$C$1:$J$3005,4,FALSE),IF($Y$14="XBE-DC08A",'All data map'!$F$1359:$J$1359, IF($Y$14="XBE-DC16A",'All data map'!$F$1360:$J$1360, IF($Y$14="XBE-DC16B",'All data map'!$F$1361:$J$1361, IF($Y$14="XBE-DC32A",'All data map'!$F$1362:$J$1362, IF($Y$14="XBE-AC08A",'All data map'!$F$1363:$J$1363, IF($Y$14="XBE-TN08A",'All data map'!$F$1364:$J$1364, IF($Y$14="XBE-TP08A",'All data map'!$F$1365:$J$1365, IF($Y$14="XBE-TN16A",'All data map'!$F$1366:$J$1366, IF($Y$14="XBE-TP16A",'All data map'!$F$1367:$J$1367, IF($Y$14="XBE-TN32A",'All data map'!$F$1368:$J$1368, IF($Y$14="XBE-TP32A",'All data map'!$F$1369:$J$1369, IF($Y$14="XBE-RY08A",'All data map'!$F$1370:$J$1370, IF($Y$14="XBE-RY08B",'All data map'!$F$1371:$J$1371, IF($Y$14="XBE-RY16A",'All data map'!$F$1372:$J$1372, IF($Y$14="XBE-DR16A",'All data map'!$F$1373:$J$1374, IF($Y$14="XBE-DN32A",'All data map'!$F$1375:$J$1376, IF($Y$14="XBF-AD04A",'All data map'!$F$1377:$J$1387, IF($Y$14="XBF-AD08A",'All data map'!$F$1388:$J$1422, IF($Y$14="XBF-AD04C",'All data map'!$F$1423:$J$1453, IF($Y$14="XBF-DV04A",'All data map'!$F$1454:$J$1470, IF($Y$14="XBF-DC04A",'All data map'!$F$1471:$J$1487, IF($Y$14="XBF-DC04B",'All data map'!$F$1488:$J$1504, IF($Y$14="XBF-DV04C",'All data map'!$F$1505:$J$1525, IF($Y$14="XBF-DC04C",'All data map'!$F$1526:$J$1550, IF($Y$14="XBF-AH04A",'All data map'!$F$1551:$J$1570, IF($Y$14="XBF-RD04A",'All data map'!$F$1571:$J$1590, IF($Y$14="XBF-RD01A",'All data map'!$F$1591:$J$1604, IF($Y$14="XBF-TC04B",'All data map'!$F$1605:$J$1650, IF($Y$14="XBF-TC04S",'All data map'!$F$1651:$J$1696, IF($Y$14="XBF-LD02S",'All data map'!$F$1697:$J$1805, IF($Y$14="XBF-HO02A",'All data map'!$F$1806:$J$1866, IF($Y$14="XBF-HD02A",'All data map'!$F$1867:$J$1927,IF($Y$14="Header",'All data map'!$F$2063:$J$2075,))))))))))))))))))))))))))))))))),BD13,FALSE),"-") -> Input | AA13: =IFERROR(HLOOKUP(VLOOKUP((VLOOKUP($Y$10,$B$10:$C$22,2,FALSE)),'All data map'!$C$1:$J$3005,5,FALSE),IF($Y$14="XBE-DC08A",'All data map'!$F$1359:$J$1359, IF($Y$14="XBE-DC16A",'All data map'!$F$1360:$J$1360, IF($Y$14="XBE-DC16B",'All data map'!$F$1361:$J$1361, IF($Y$14="XBE-DC32A",'All data map'!$F$1362:$J$1362, IF($Y$14="XBE-AC08A",'All data map'!$F$1363:$J$1363, IF($Y$14="XBE-TN08A",'All data map'!$F$1364:$J$1364, IF($Y$14="XBE-TP08A",'All data map'!$F$1365:$J$1365, IF($Y$14="XBE-TN16A",'All data map'!$F$1366:$J$1366, IF($Y$14="XBE-TP16A",'All data map'!$F$1367:$J$1367, IF($Y$14="XBE-TN32A",'All data map'!$F$1368:$J$1368, IF($Y$14="XBE-TP32A",'All data map'!$F$1369:$J$1369, IF($Y$14="XBE-RY08A",'All data map'!$F$1370:$J$1370, IF($Y$14="XBE-RY08B",'All data map'!$F$1371:$J$1371, IF($Y$14="XBE-RY16A",'All data map'!$F$1372:$J$1372, IF($Y$14="XBE-DR16A",'All data map'!$F$1373:$J$1374, IF($Y$14="XBE-DN32A",'All data map'!$F$1375:$J$1376, IF($Y$14="XBF-AD04A",'All data map'!$F$1377:$J$1387, IF($Y$14="XBF-AD08A",'All data map'!$F$1388:$J$1422, IF($Y$14="XBF-AD04C",'All data map'!$F$1423:$J$1453, IF($Y$14="XBF-DV04A",'All data map'!$F$1454:$J$1470, IF($Y$14="XBF-DC04A",'All data map'!$F$1471:$J$1487, IF($Y$14="XBF-DC04B",'All data map'!$F$1488:$J$1504, IF($Y$14="XBF-DV04C",'All data map'!$F$1505:$J$1525, IF($Y$14="XBF-DC04C",'All data map'!$F$1526:$J$1550, IF($Y$14="XBF-AH04A",'All data map'!$F$1551:$J$1570, IF($Y$14="XBF-RD04A",'All data map'!$F$1571:$J$1590, IF($Y$14="XBF-RD01A",'All data map'!$F$1591:$J$1604, IF($Y$14="XBF-TC04B",'All data map'!$F$1605:$J$1650, IF($Y$14="XBF-TC04S",'All data map'!$F$1651:$J$1696, IF($Y$14="XBF-LD02S",'All data map'!$F$1697:$J$1805, IF($Y$14="XBF-HO02A",'All data map'!$F$1806:$J$1866, IF($Y$14="XBF-HD02A",'All data map'!$F$1867:$J$1927,IF($Y$14="Header",'All data map'!$F$2063:$H$2075,0))))))))))))))))))))))))))))))))),BE13,FALSE),"-") -> XBF-TC04B_CH3_ADJERR | AB13: =IFERROR(HLOOKUP(VLOOKUP((VLOOKUP($Y$10,$B$10:$C$22,2,FALSE)),'All data map'!$C$1:$J$3005,6,FALSE),IF($Y$14="XBE-DC08A",'All data map'!$F$1359:$J$1359, IF($Y$14="XBE-DC16A",'All data map'!$F$1360:$J$1360, IF($Y$14="XBE-DC16B",'All data map'!$F$1361:$J$1361, IF($Y$14="XBE-DC32A",'All data map'!$F$1362:$J$1362, IF($Y$14="XBE-AC08A",'All data map'!$F$1363:$J$1363, IF($Y$14="XBE-TN08A",'All data map'!$F$1364:$J$1364, IF($Y$14="XBE-TP08A",'All data map'!$F$1365:$J$1365, IF($Y$14="XBE-TN16A",'All data map'!$F$1366:$J$1366, IF($Y$14="XBE-TP16A",'All data map'!$F$1367:$J$1367, IF($Y$14="XBE-TN32A",'All data map'!$F$1368:$J$1368, IF($Y$14="XBE-TP32A",'All data map'!$F$1369:$J$1369, IF($Y$14="XBE-RY08A",'All data map'!$F$1370:$J$1370, IF($Y$14="XBE-RY08B",'All data map'!$F$1371:$J$1371, IF($Y$14="XBE-RY16A",'All data map'!$F$1372:$J$1372, IF($Y$14="XBE-DR16A",'All data map'!$F$1373:$J$1374, IF($Y$14="XBE-DN32A",'All data map'!$F$1375:$J$1376, IF($Y$14="XBF-AD04A",'All data map'!$F$1377:$J$1387, IF($Y$14="XBF-AD08A",'All data map'!$F$1388:$J$1422, IF($Y$14="XBF-AD04C",'All data map'!$F$1423:$J$1453, IF($Y$14="XBF-DV04A",'All data map'!$F$1454:$J$1470, IF($Y$14="XBF-DC04A",'All data map'!$F$1471:$J$1487, IF($Y$14="XBF-DC04B",'All data map'!$F$1488:$J$1504, IF($Y$14="XBF-DV04C",'All data map'!$F$1505:$J$1525, IF($Y$14="XBF-DC04C",'All data map'!$F$1526:$J$1550, IF($Y$14="XBF-AH04A",'All data map'!$F$1551:$J$1570, IF($Y$14="XBF-RD04A",'All data map'!$F$1571:$J$1590, IF($Y$14="XBF-RD01A",'All data map'!$F$1591:$J$1604, IF($Y$14="XBF-TC04B",'All data map'!$F$1605:$J$1650, IF($Y$14="XBF-TC04S",'All data map'!$F$1651:$J$1696, IF($Y$14="XBF-LD02S",'All data map'!$F$1697:$J$1805, IF($Y$14="XBF-HO02A",'All data map'!$F$1806:$J$1866, IF($Y$14="XBF-HD02A",'All data map'!$F$1867:$J$1927,IF($Y$14="Header",'All data map'!$F$2063:$J$2075,))))))))))))))))))))))))))))))))),BF13,FALSE),"-") -> BIT | AC13: =IFERROR(HLOOKUP(VLOOKUP((VLOOKUP($Y$10,$B$10:$C$22,2,FALSE)),'All data map'!$C$1:$J$3005,7,FALSE),IF($Y$14="XBE-DC08A",'All data map'!$F$1359:$J$1359, IF($Y$14="XBE-DC16A",'All data map'!$F$1360:$J$1360, IF($Y$14="XBE-DC16B",'All data map'!$F$1361:$J$1361, IF($Y$14="XBE-DC32A",'All data map'!$F$1362:$J$1362, IF($Y$14="XBE-AC08A",'All data map'!$F$1363:$J$1363, IF($Y$14="XBE-TN08A",'All data map'!$F$1364:$J$1364, IF($Y$14="XBE-TP08A",'All data map'!$F$1365:$J$1365, IF($Y$14="XBE-TN16A",'All data map'!$F$1366:$J$1366, IF($Y$14="XBE-TP16A",'All data map'!$F$1367:$J$1367, IF($Y$14="XBE-TN32A",'All data map'!$F$1368:$J$1368, IF($Y$14="XBE-TP32A",'All data map'!$F$1369:$J$1369, IF($Y$14="XBE-RY08A",'All data map'!$F$1370:$J$1370, IF($Y$14="XBE-RY08B",'All data map'!$F$1371:$J$1371, IF($Y$14="XBE-RY16A",'All data map'!$F$1372:$J$1372, IF($Y$14="XBE-DR16A",'All data map'!$F$1373:$J$1374, IF($Y$14="XBE-DN32A",'All data map'!$F$1375:$J$1376, IF($Y$14="XBF-AD04A",'All data map'!$F$1377:$J$1387, IF($Y$14="XBF-AD08A",'All data map'!$F$1388:$J$1422, IF($Y$14="XBF-AD04C",'All data map'!$F$1423:$J$1453, IF($Y$14="XBF-DV04A",'All data map'!$F$1454:$J$1470, IF($Y$14="XBF-DC04A",'All data map'!$F$1471:$J$1487, IF($Y$14="XBF-DC04B",'All data map'!$F$1488:$J$1504, IF($Y$14="XBF-DV04C",'All data map'!$F$1505:$J$1525, IF($Y$14="XBF-DC04C",'All data map'!$F$1526:$J$1550, IF($Y$14="XBF-AH04A",'All data map'!$F$1551:$J$1570, IF($Y$14="XBF-RD04A",'All data map'!$F$1571:$J$1590, IF($Y$14="XBF-RD01A",'All data map'!$F$1591:$J$1604, IF($Y$14="XBF-TC04B",'All data map'!$F$1605:$J$1650, IF($Y$14="XBF-TC04S",'All data map'!$F$1651:$J$1696, IF($Y$14="XBF-LD02S",'All data map'!$F$1697:$J$1805, IF($Y$14="XBF-HO02A",'All data map'!$F$1806:$J$1866, IF($Y$14="XBF-HD02A",'All data map'!$F$1867:$J$1927,IF($Y$14="Header",'All data map'!$F$2063:$J$2075,))))))))))))))))))))))))))))))))),BG13,FALSE),"-") -> 0.3 | AD13: =IFERROR(HLOOKUP(VLOOKUP((VLOOKUP($Y$10,$B$10:$C$22,2,FALSE)),'All data map'!$C$1:$J$3005,8,FALSE),IF($Y$14="XBE-DC08A",'All data map'!$F$1359:$J$1359, IF($Y$14="XBE-DC16A",'All data map'!$F$1360:$J$1360, IF($Y$14="XBE-DC16B",'All data map'!$F$1361:$J$1361, IF($Y$14="XBE-DC32A",'All data map'!$F$1362:$J$1362, IF($Y$14="XBE-AC08A",'All data map'!$F$1363:$J$1363, IF($Y$14="XBE-TN08A",'All data map'!$F$1364:$J$1364, IF($Y$14="XBE-TP08A",'All data map'!$F$1365:$J$1365, IF($Y$14="XBE-TN16A",'All data map'!$F$1366:$J$1366, IF($Y$14="XBE-TP16A",'All data map'!$F$1367:$J$1367, IF($Y$14="XBE-TN32A",'All data map'!$F$1368:$J$1368, IF($Y$14="XBE-TP32A",'All data map'!$F$1369:$J$1369, IF($Y$14="XBE-RY08A",'All data map'!$F$1370:$J$1370, IF($Y$14="XBE-RY08B",'All data map'!$F$1371:$J$1371, IF($Y$14="XBE-RY16A",'All data map'!$F$1372:$J$1372, IF($Y$14="XBE-DR16A",'All data map'!$F$1373:$J$1374, IF($Y$14="XBE-DN32A",'All data map'!$F$1375:$J$1376, IF($Y$14="XBF-AD04A",'All data map'!$F$1377:$J$1387, IF($Y$14="XBF-AD08A",'All data map'!$F$1388:$J$1422, IF($Y$14="XBF-AD04C",'All data map'!$F$1423:$J$1453, IF($Y$14="XBF-DV04A",'All data map'!$F$1454:$J$1470, IF($Y$14="XBF-DC04A",'All data map'!$F$1471:$J$1487, IF($Y$14="XBF-DC04B",'All data map'!$F$1488:$J$1504, IF($Y$14="XBF-DV04C",'All data map'!$F$1505:$J$1525, IF($Y$14="XBF-DC04C",'All data map'!$F$1526:$J$1550, IF($Y$14="XBF-AH04A",'All data map'!$F$1551:$J$1570, IF($Y$14="XBF-RD04A",'All data map'!$F$1571:$J$1590, IF($Y$14="XBF-RD01A",'All data map'!$F$1591:$J$1604, IF($Y$14="XBF-TC04B",'All data map'!$F$1605:$J$1650, IF($Y$14="XBF-TC04S",'All data map'!$F$1651:$J$1696, IF($Y$14="XBF-LD02S",'All data map'!$F$1697:$J$1805, IF($Y$14="XBF-HO02A",'All data map'!$F$1806:$J$1866, IF($Y$14="XBF-HD02A",'All data map'!$F$1867:$J$1927,IF($Y$14="Header",'All data map'!$F$2063:$J$2075,))))))))))))))))))))))))))))))))),BH13,FALSE),"-") -> Temperature input module : Channel 3 offset/gain error flag | BB13: 4 | BC13: 4 | BD13: 4 | BE13: 4 | BF13: 4 | BG13: 4 | BH13: 4 | BI13: 4 | BJ13: 4 | BK13: 4 | BL13: 4 | BM13: 4 | BN13: 4 | BO13: 4 | BP13: 4 | BQ13: 4 | BR13: 4
B14: 3 | C14: XBF-TC04B | D14: =IFERROR(VLOOKUP(C14,'refresh size'!C:E,2,FALSE),0) -> 40 | E14: =IFERROR(VLOOKUP(C14,'refresh size'!C:E,3,FALSE),0) -> 2 | F14: =IF(LEN(C14)>0,IF(D14>0,MAX(F$10:F13)+D14,"-"),"-") -> 62 | G14: =IF(LEN(C14)>0,IF(E14>0,MAX(G$10:G13)+E14,0),0) -> 20 | H14: =B14*8 -> 24 | I14: =B14*8 -> 24 | J14: =B14*64 -> 192 | K14: =IFERROR(F14-D14,0) -> 22 | L14: =IFERROR(G14-E14,0) -> 18 | M14: =$M$9 -> MW | N14: =IF(D14,IF(D14,$N$9+(K14/2),0),"-") -> 11 | O14: =$M$9 -> MW | P14: =IF(E14,IF(E14,$P$9+(L14/2),0),"-") -> 109 | Q14: =IF(D14<>0,"H302"&TEXT(DEC2HEX(K14/2,2),"00"),0) -> H3020B | R14: =D14/2 -> 20 | S14: =IF(E14<>0,"H402"&TEXT(DEC2HEX(L14/2,2),"00"),0) -> H40209 | T14: =E14/2 -> 1 | U14: =IF(D14<>0,"305"&TEXT(K14/2+12+$V$5,"00"),0) -> 30523 | V14: =D14/2 -> 20 | W14: =IF(E14<>0,"405"&TEXT(L14/2+12+$V$5,"00"),0) -> 40521 | X14: =E14/2 -> 1 | Y14: =IF(Y10="Header","Header",(VLOOKUP($Y$10,$B$10:$C$22,2,FALSE))) -> XBF-TC04B | Z14: =IFERROR(HLOOKUP(VLOOKUP((VLOOKUP($Y$10,$B$10:$C$22,2,FALSE)),'All data map'!$C$1:$J$3005,4,FALSE),IF($Y$14="XBE-DC08A",'All data map'!$F$1359:$J$1359, IF($Y$14="XBE-DC16A",'All data map'!$F$1360:$J$1360, IF($Y$14="XBE-DC16B",'All data map'!$F$1361:$J$1361, IF($Y$14="XBE-DC32A",'All data map'!$F$1362:$J$1362, IF($Y$14="XBE-AC08A",'All data map'!$F$1363:$J$1363, IF($Y$14="XBE-TN08A",'All data map'!$F$1364:$J$1364, IF($Y$14="XBE-TP08A",'All data map'!$F$1365:$J$1365, IF($Y$14="XBE-TN16A",'All data map'!$F$1366:$J$1366, IF($Y$14="XBE-TP16A",'All data map'!$F$1367:$J$1367, IF($Y$14="XBE-TN32A",'All data map'!$F$1368:$J$1368, IF($Y$14="XBE-TP32A",'All data map'!$F$1369:$J$1369, IF($Y$14="XBE-RY08A",'All data map'!$F$1370:$J$1370, IF($Y$14="XBE-RY08B",'All data map'!$F$1371:$J$1371, IF($Y$14="XBE-RY16A",'All data map'!$F$1372:$J$1372, IF($Y$14="XBE-DR16A",'All data map'!$F$1373:$J$1374, IF($Y$14="XBE-DN32A",'All data map'!$F$1375:$J$1376, IF($Y$14="XBF-AD04A",'All data map'!$F$1377:$J$1387, IF($Y$14="XBF-AD08A",'All data map'!$F$1388:$J$1422, IF($Y$14="XBF-AD04C",'All data map'!$F$1423:$J$1453, IF($Y$14="XBF-DV04A",'All data map'!$F$1454:$J$1470, IF($Y$14="XBF-DC04A",'All data map'!$F$1471:$J$1487, IF($Y$14="XBF-DC04B",'All data map'!$F$1488:$J$1504, IF($Y$14="XBF-DV04C",'All data map'!$F$1505:$J$1525, IF($Y$14="XBF-DC04C",'All data map'!$F$1526:$J$1550, IF($Y$14="XBF-AH04A",'All data map'!$F$1551:$J$1570, IF($Y$14="XBF-RD04A",'All data map'!$F$1571:$J$1590, IF($Y$14="XBF-RD01A",'All data map'!$F$1591:$J$1604, IF($Y$14="XBF-TC04B",'All data map'!$F$1605:$J$1650, IF($Y$14="XBF-TC04S",'All data map'!$F$1651:$J$1696, IF($Y$14="XBF-LD02S",'All data map'!$F$1697:$J$1805, IF($Y$14="XBF-HO02A",'All data map'!$F$1806:$J$1866, IF($Y$14="XBF-HD02A",'All data map'!$F$1867:$J$1927,IF($Y$14="Header",'All data map'!$F$2063:$J$2075,))))))))))))))))))))))))))))))))),BD14,FALSE),"-") -> Input | AA14: =IFERROR(HLOOKUP(VLOOKUP((VLOOKUP($Y$10,$B$10:$C$22,2,FALSE)),'All data map'!$C$1:$J$3005,5,FALSE),IF($Y$14="XBE-DC08A",'All data map'!$F$1359:$J$1359, IF($Y$14="XBE-DC16A",'All data map'!$F$1360:$J$1360, IF($Y$14="XBE-DC16B",'All data map'!$F$1361:$J$1361, IF($Y$14="XBE-DC32A",'All data map'!$F$1362:$J$1362, IF($Y$14="XBE-AC08A",'All data map'!$F$1363:$J$1363, IF($Y$14="XBE-TN08A",'All data map'!$F$1364:$J$1364, IF($Y$14="XBE-TP08A",'All data map'!$F$1365:$J$1365, IF($Y$14="XBE-TN16A",'All data map'!$F$1366:$J$1366, IF($Y$14="XBE-TP16A",'All data map'!$F$1367:$J$1367, IF($Y$14="XBE-TN32A",'All data map'!$F$1368:$J$1368, IF($Y$14="XBE-TP32A",'All data map'!$F$1369:$J$1369, IF($Y$14="XBE-RY08A",'All data map'!$F$1370:$J$1370, IF($Y$14="XBE-RY08B",'All data map'!$F$1371:$J$1371, IF($Y$14="XBE-RY16A",'All data map'!$F$1372:$J$1372, IF($Y$14="XBE-DR16A",'All data map'!$F$1373:$J$1374, IF($Y$14="XBE-DN32A",'All data map'!$F$1375:$J$1376, IF($Y$14="XBF-AD04A",'All data map'!$F$1377:$J$1387, IF($Y$14="XBF-AD08A",'All data map'!$F$1388:$J$1422, IF($Y$14="XBF-AD04C",'All data map'!$F$1423:$J$1453, IF($Y$14="XBF-DV04A",'All data map'!$F$1454:$J$1470, IF($Y$14="XBF-DC04A",'All data map'!$F$1471:$J$1487, IF($Y$14="XBF-DC04B",'All data map'!$F$1488:$J$1504, IF($Y$14="XBF-DV04C",'All data map'!$F$1505:$J$1525, IF($Y$14="XBF-DC04C",'All data map'!$F$1526:$J$1550, IF($Y$14="XBF-AH04A",'All data map'!$F$1551:$J$1570, IF($Y$14="XBF-RD04A",'All data map'!$F$1571:$J$1590, IF($Y$14="XBF-RD01A",'All data map'!$F$1591:$J$1604, IF($Y$14="XBF-TC04B",'All data map'!$F$1605:$J$1650, IF($Y$14="XBF-TC04S",'All data map'!$F$1651:$J$1696, IF($Y$14="XBF-LD02S",'All data map'!$F$1697:$J$1805, IF($Y$14="XBF-HO02A",'All data map'!$F$1806:$J$1866, IF($Y$14="XBF-HD02A",'All data map'!$F$1867:$J$1927,IF($Y$14="Header",'All data map'!$F$2063:$H$2075,0))))))))))))))))))))))))))))))))),BE14,FALSE),"-") -> XBF-TC04B_EXT_PWR_ERR | AB14: =IFERROR(HLOOKUP(VLOOKUP((VLOOKUP($Y$10,$B$10:$C$22,2,FALSE)),'All data map'!$C$1:$J$3005,6,FALSE),IF($Y$14="XBE-DC08A",'All data map'!$F$1359:$J$1359, IF($Y$14="XBE-DC16A",'All data map'!$F$1360:$J$1360, IF($Y$14="XBE-DC16B",'All data map'!$F$1361:$J$1361, IF($Y$14="XBE-DC32A",'All data map'!$F$1362:$J$1362, IF($Y$14="XBE-AC08A",'All data map'!$F$1363:$J$1363, IF($Y$14="XBE-TN08A",'All data map'!$F$1364:$J$1364, IF($Y$14="XBE-TP08A",'All data map'!$F$1365:$J$1365, IF($Y$14="XBE-TN16A",'All data map'!$F$1366:$J$1366, IF($Y$14="XBE-TP16A",'All data map'!$F$1367:$J$1367, IF($Y$14="XBE-TN32A",'All data map'!$F$1368:$J$1368, IF($Y$14="XBE-TP32A",'All data map'!$F$1369:$J$1369, IF($Y$14="XBE-RY08A",'All data map'!$F$1370:$J$1370, IF($Y$14="XBE-RY08B",'All data map'!$F$1371:$J$1371, IF($Y$14="XBE-RY16A",'All data map'!$F$1372:$J$1372, IF($Y$14="XBE-DR16A",'All data map'!$F$1373:$J$1374, IF($Y$14="XBE-DN32A",'All data map'!$F$1375:$J$1376, IF($Y$14="XBF-AD04A",'All data map'!$F$1377:$J$1387, IF($Y$14="XBF-AD08A",'All data map'!$F$1388:$J$1422, IF($Y$14="XBF-AD04C",'All data map'!$F$1423:$J$1453, IF($Y$14="XBF-DV04A",'All data map'!$F$1454:$J$1470, IF($Y$14="XBF-DC04A",'All data map'!$F$1471:$J$1487, IF($Y$14="XBF-DC04B",'All data map'!$F$1488:$J$1504, IF($Y$14="XBF-DV04C",'All data map'!$F$1505:$J$1525, IF($Y$14="XBF-DC04C",'All data map'!$F$1526:$J$1550, IF($Y$14="XBF-AH04A",'All data map'!$F$1551:$J$1570, IF($Y$14="XBF-RD04A",'All data map'!$F$1571:$J$1590, IF($Y$14="XBF-RD01A",'All data map'!$F$1591:$J$1604, IF($Y$14="XBF-TC04B",'All data map'!$F$1605:$J$1650, IF($Y$14="XBF-TC04S",'All data map'!$F$1651:$J$1696, IF($Y$14="XBF-LD02S",'All data map'!$F$1697:$J$1805, IF($Y$14="XBF-HO02A",'All data map'!$F$1806:$J$1866, IF($Y$14="XBF-HD02A",'All data map'!$F$1867:$J$1927,IF($Y$14="Header",'All data map'!$F$2063:$J$2075,))))))))))))))))))))))))))))))))),BF14,FALSE),"-") -> BIT | AC14: =IFERROR(HLOOKUP(VLOOKUP((VLOOKUP($Y$10,$B$10:$C$22,2,FALSE)),'All data map'!$C$1:$J$3005,7,FALSE),IF($Y$14="XBE-DC08A",'All data map'!$F$1359:$J$1359, IF($Y$14="XBE-DC16A",'All data map'!$F$1360:$J$1360, IF($Y$14="XBE-DC16B",'All data map'!$F$1361:$J$1361, IF($Y$14="XBE-DC32A",'All data map'!$F$1362:$J$1362, IF($Y$14="XBE-AC08A",'All data map'!$F$1363:$J$1363, IF($Y$14="XBE-TN08A",'All data map'!$F$1364:$J$1364, IF($Y$14="XBE-TP08A",'All data map'!$F$1365:$J$1365, IF($Y$14="XBE-TN16A",'All data map'!$F$1366:$J$1366, IF($Y$14="XBE-TP16A",'All data map'!$F$1367:$J$1367, IF($Y$14="XBE-TN32A",'All data map'!$F$1368:$J$1368, IF($Y$14="XBE-TP32A",'All data map'!$F$1369:$J$1369, IF($Y$14="XBE-RY08A",'All data map'!$F$1370:$J$1370, IF($Y$14="XBE-RY08B",'All data map'!$F$1371:$J$1371, IF($Y$14="XBE-RY16A",'All data map'!$F$1372:$J$1372, IF($Y$14="XBE-DR16A",'All data map'!$F$1373:$J$1374, IF($Y$14="XBE-DN32A",'All data map'!$F$1375:$J$1376, IF($Y$14="XBF-AD04A",'All data map'!$F$1377:$J$1387, IF($Y$14="XBF-AD08A",'All data map'!$F$1388:$J$1422, IF($Y$14="XBF-AD04C",'All data map'!$F$1423:$J$1453, IF($Y$14="XBF-DV04A",'All data map'!$F$1454:$J$1470, IF($Y$14="XBF-DC04A",'All data map'!$F$1471:$J$1487, IF($Y$14="XBF-DC04B",'All data map'!$F$1488:$J$1504, IF($Y$14="XBF-DV04C",'All data map'!$F$1505:$J$1525, IF($Y$14="XBF-DC04C",'All data map'!$F$1526:$J$1550, IF($Y$14="XBF-AH04A",'All data map'!$F$1551:$J$1570, IF($Y$14="XBF-RD04A",'All data map'!$F$1571:$J$1590, IF($Y$14="XBF-RD01A",'All data map'!$F$1591:$J$1604, IF($Y$14="XBF-TC04B",'All data map'!$F$1605:$J$1650, IF($Y$14="XBF-TC04S",'All data map'!$F$1651:$J$1696, IF($Y$14="XBF-LD02S",'All data map'!$F$1697:$J$1805, IF($Y$14="XBF-HO02A",'All data map'!$F$1806:$J$1866, IF($Y$14="XBF-HD02A",'All data map'!$F$1867:$J$1927,IF($Y$14="Header",'All data map'!$F$2063:$J$2075,))))))))))))))))))))))))))))))))),BG14,FALSE),"-") -> 0.C | AD14: =IFERROR(HLOOKUP(VLOOKUP((VLOOKUP($Y$10,$B$10:$C$22,2,FALSE)),'All data map'!$C$1:$J$3005,8,FALSE),IF($Y$14="XBE-DC08A",'All data map'!$F$1359:$J$1359, IF($Y$14="XBE-DC16A",'All data map'!$F$1360:$J$1360, IF($Y$14="XBE-DC16B",'All data map'!$F$1361:$J$1361, IF($Y$14="XBE-DC32A",'All data map'!$F$1362:$J$1362, IF($Y$14="XBE-AC08A",'All data map'!$F$1363:$J$1363, IF($Y$14="XBE-TN08A",'All data map'!$F$1364:$J$1364, IF($Y$14="XBE-TP08A",'All data map'!$F$1365:$J$1365, IF($Y$14="XBE-TN16A",'All data map'!$F$1366:$J$1366, IF($Y$14="XBE-TP16A",'All data map'!$F$1367:$J$1367, IF($Y$14="XBE-TN32A",'All data map'!$F$1368:$J$1368, IF($Y$14="XBE-TP32A",'All data map'!$F$1369:$J$1369, IF($Y$14="XBE-RY08A",'All data map'!$F$1370:$J$1370, IF($Y$14="XBE-RY08B",'All data map'!$F$1371:$J$1371, IF($Y$14="XBE-RY16A",'All data map'!$F$1372:$J$1372, IF($Y$14="XBE-DR16A",'All data map'!$F$1373:$J$1374, IF($Y$14="XBE-DN32A",'All data map'!$F$1375:$J$1376, IF($Y$14="XBF-AD04A",'All data map'!$F$1377:$J$1387, IF($Y$14="XBF-AD08A",'All data map'!$F$1388:$J$1422, IF($Y$14="XBF-AD04C",'All data map'!$F$1423:$J$1453, IF($Y$14="XBF-DV04A",'All data map'!$F$1454:$J$1470, IF($Y$14="XBF-DC04A",'All data map'!$F$1471:$J$1487, IF($Y$14="XBF-DC04B",'All data map'!$F$1488:$J$1504, IF($Y$14="XBF-DV04C",'All data map'!$F$1505:$J$1525, IF($Y$14="XBF-DC04C",'All data map'!$F$1526:$J$1550, IF($Y$14="XBF-AH04A",'All data map'!$F$1551:$J$1570, IF($Y$14="XBF-RD04A",'All data map'!$F$1571:$J$1590, IF($Y$14="XBF-RD01A",'All data map'!$F$1591:$J$1604, IF($Y$14="XBF-TC04B",'All data map'!$F$1605:$J$1650, IF($Y$14="XBF-TC04S",'All data map'!$F$1651:$J$1696, IF($Y$14="XBF-LD02S",'All data map'!$F$1697:$J$1805, IF($Y$14="XBF-HO02A",'All data map'!$F$1806:$J$1866, IF($Y$14="XBF-HD02A",'All data map'!$F$1867:$J$1927,IF($Y$14="Header",'All data map'!$F$2063:$J$2075,))))))))))))))))))))))))))))))))),BH14,FALSE),"-") -> Temperature input module : External power error | BB14: 5 | BC14: 5 | BD14: 5 | BE14: 5 | BF14: 5 | BG14: 5 | BH14: 5 | BI14: 5 | BJ14: 5 | BK14: 5 | BL14: 5 | BM14: 5 | BN14: 5 | BO14: 5 | BP14: 5 | BQ14: 5 | BR14: 5
